Workbook

Sheet products_2026
A1: product_id | B1: product_name | C1: product_category | D1: product_price_aud | E1: seller_id
A2: PROD00001 | B2: Hair Strengthening Mask shea butter 4 pack | C2: Beauty | D2: 33.08 | E2: SELL0001
A3: PROD00002 | B3: Hair Strengthening Mask shea butter 2 pack | C3: Beauty | D3: 31.97 | E3: SELL0001
A4: PROD00003 | B4: Rain Jacket Light Green | C4: Clothes | D4: 47.09 | E4: SELL0002
A5: PROD00004 | B5: Wireless Keyboard | C5: Electronics | D5: 85.97 | E5: SELL0003
A6: PROD00005 | B6: Wall Clock - Minimalist (Blue) | C6: Home | D6: 96.77 | E6: SELL0004
A7: PROD00006 | B7: Highlighter Set Bright 4 pen | C7: Stationery | D7: 4.47 | E7: SELL0005
A8: PROD00007 | B8: Slime Lab Blue 8pc | C8: Toys | D8: 38.25 | E8: SELL0006
A9: PROD00008 | B9: Slime Lab Green 8pc | C9: Toys | D9: 38.25 | E9: SELL0006
A10: PROD00009 | B10: Heat Therapy Pad | C10: Health | D10: 79.16 | E10: SELL0007
A11: PROD00010 | B11: Summer Dress - Floral | C11: Clothes | D11: 30.71 | E11: SELL0008
A12: PROD00011 | B12: Summer Dress - Floral Blue | C12: Clothes | D12: 30.12 | E12: SELL0008
A13: PROD00012 | B13: Whiteboard Markers - 6 pack | C13: Stationery | D13: 7.06 | E13: SELL0010
... A15: PROD00014 | B15: Waterproof Picnic Mat 100x100 | C15: Outdoor | D15: 46.45 | E15: SELL0012
A16: PROD00015 | B16: Garden Lights 4 pack Solar Power | C16: Outdoor | D16: 48.06 | E16: SELL0014 | H16: =SUM(Table3[product_price_aud]) -> 19738.69
A17: PROD00016 | B17: Stainless Steel Grill Basket XL | C17: Outdoor | D17: 73.55 | E17: SELL0015
A18: PROD00017 | B18: BBQ Skewers - 12 pack (Bamboo) | C18: Outdoor | D18: 13.71 | E18: SELL0016
A19: PROD00018 | B19: Waterproof Picnic Mat 100x100 | C19: Outdoor | D19: 40.12 | E19: SELL0016
A20: PROD00019 | B20: Hydrating Face Mist | C20: Beauty | D20: 10.94 | E20: SELL0017
A21: PROD00020 | B21: BBQ Skewers - 12 pack (Stainless Steel) | C21: Outdoor | D21: 15.05 | E21: SELL0009
A22: PROD00021 | B22: Garden Lights 10 pack Solar Power | C22: Outdoor | D22: 113.99 | E22: SELL0017
A23: PROD00022 | B23: BBQ Skewers - 24 pack (Stainless Steel) | C23: Outdoor | D23: 27.05 | E23: SELL0018
A24: PROD00023 | B24: Stainless Steel Grill Basket XL | C24: Outdoor | D24: 98.38 | E24: SELL0018
A25: PROD00024 | B25: BBQ Skewers - 24 pack (Bamboo) | C25: Outdoor | D25: 23.99 | E25: SELL0018
A26: PROD00025 | B26: Vit C Serum Revitalising 50ml | C26: Beauty | D26: 11.28 | E26: SELL0018
A27: PROD00026 | B27: Digital Thermometer (Yellow) | C27: Health | D27: 43.18 | E27: SELL0018
A28: PROD00027 | B28: Pendant Necklace - Rose Gold | C28: Jewellery | D28: 28.22 | E28: SELL0019
... A251: PROD00250 | B251: Highlighter 4pc Yellow | C251: Stationery | D251: 6.18 | E251: SELL0080
A252: PROD00251 | B252: Waterproof Picnic Mat Pattern | C252: Outdoor | D252: 70.39 | E252: SELL0081 | G252: =SUM(D15:D462) -> 19141.16
A253: PROD00252 | B253: Men’s Chino Shorts M | C253: Clothes | D253: 56.67 | E253: SELL0081
A254: PROD00253 | B254: Milk Chocolate Selection Box | C254: Gift_Sets | D254: 19.09 | E254: SELL0081
A255: PROD00254 | B255: Charm Bracelet 3 charms silver | C255: Jewellery | D255: 56.43 | E255: SELL0081
A256: PROD00255 | B256: Wood Chips - Hickory | C256: Outdoor | D256: 31.66 | E256: SELL0081
A257: PROD00256 | B257: Disposible Mini Grill | C257: Outdoor | D257: 48.14 | E257: SELL0081
A258: PROD00257 | B258: Face Mist Vitamin E | C258: Beauty | D258: 17.28 | E258: SELL0082
A259: PROD00258 | B259: Luxury Makeup Sponge Blend | C259: Beauty | D259: 31.59 | E259: SELL0082
A260: PROD00259 | B260: Hair Strengthening Mask shea butter | C260: Beauty | D260: 22.28 | E260: SELL0082
A261: PROD00260 | B261: Aloe Vera Gel 150ml | C261: Beauty | D261: 11.75 | E261: SELL0083
A262: PROD00261 | B262: Aloe Vera Gel 200ml | C262: Beauty | D262: 6.91 | E262: SELL0083
A263: PROD00262 | B263: Vitamin C Serum 50ml | C263: Beauty | D263: 15.09 | E263: SELL0001
...

Sheet Rough data
A1: product_category | B1: product_id | C1: product_price | D1: product_name | E1: seller_id | F1: seller_user | G1: product_quantity | H1: product_revenue
A2: =VLOOKUP(B2,Table3[[#Headers],[#Data]],3,FALSE) -> Beauty | B2: PROD00001 | C2: =VLOOKUP(B2,Table3[[#Headers],[#Data]],4, FALSE) -> 33.08 | D2: =VLOOKUP('Rough data'!B2,Table3[[#Headers],[#Data]],2,FALSE) -> Hair Strengthening Mask shea butter 4 pack | E2: =VLOOKUP(B2,Table3[[#Headers],[#Data]],5,FALSE) -> SELL0001 | F2: =VLOOKUP(E2,Table2[[#Headers],[#Data],[seller_id]:[seller_user]],2,FALSE) -> beauty4everyone | G2: 1 | H2: =G2*C2 -> 33.08
A3: =VLOOKUP(B3,Table3[[#Headers],[#Data]],3,FALSE) -> Stationery | B3: PROD00006 | C3: =VLOOKUP(B3,Table3[[#Headers],[#Data]],4, FALSE) -> 4.47 | D3: =VLOOKUP('Rough data'!B3,Table3[[#Headers],[#Data]],2,FALSE) -> Highlighter Set Bright 4 pen | E3: =VLOOKUP(B3,Table3[[#Headers],[#Data]],5,FALSE) -> SELL0005 | F3: =VLOOKUP(E3,Table2[[#Headers],[#Data],[seller_id]:[seller_user]],2,FALSE) -> pensandthings | G3: 2 | H3: =G3*C3 -> 8.94
A4: =VLOOKUP(B4,Table3[[#Headers],[#Data]],3,FALSE) -> Stationery | B4: PROD00006 | C4: =VLOOKUP(B4,Table3[[#Headers],[#Data]],4, FALSE) -> 4.47 | D4: =VLOOKUP('Rough data'!B4,Table3[[#Headers],[#Data]],2,FALSE) -> Highlighter Set Bright 4 pen | E4: =VLOOKUP(B4,Table3[[#Headers],[#Data]],5,FALSE) -> SELL0005 | F4: =VLOOKUP(E4,Table2[[#Headers],[#Data],[seller_id]:[seller_user]],2,FALSE) -> pensandthings | G4: 1 | H4: =G4*C4 -> 4.47
A5: =VLOOKUP(B5,Table3[[#Headers],[#Data]],3,FALSE) -> Toys | B5: PROD00007 | C5: =VLOOKUP(B5,Table3[[#Headers],[#Data]],4, FALSE) -> 38.25 | D5: =VLOOKUP('Rough data'!B5,Table3[[#Headers],[#Data]],2,FALSE) -> Slime Lab Blue 8pc | E5: =VLOOKUP(B5,Table3[[#Headers],[#Data]],5,FALSE) -> SELL0006 | F5: =VLOOKUP(E5,Table2[[#Headers],[#Data],[seller_id]:[seller_user]],2,FALSE) -> toysyay | G5: 1 | H5: =G5*C5 -> 38.25
A6: =VLOOKUP(B6,Table3[[#Headers],[#Data]],3,FALSE) -> Toys | B6: PROD00008 | C6: =VLOOKUP(B6,Table3[[#Headers],[#Data]],4, FALSE) -> 38.25 | D6: =VLOOKUP('Rough data'!B6,Table3[[#Headers],[#Data]],2,FALSE) -> Slime Lab Green 8pc | E6: =VLOOKUP(B6,Table3[[#Headers],[#Data]],5,FALSE) -> SELL0006 | F6: =VLOOKUP(E6,Table2[[#Headers],[#Data],[seller_id]:[seller_user]],2,FALSE) -> toysyay | G6: 1 | H6: =G6*C6 -> 38.25
A7: =VLOOKUP(B7,Table3[[#Headers],[#Data]],3,FALSE) -> Toys | B7: PROD00008 | C7: =VLOOKUP(B7,Table3[[#Headers],[#Data]],4, FALSE) -> 38.25 | D7: =VLOOKUP('Rough data'!B7,Table3[[#Headers],[#Data]],2,FALSE) -> Slime Lab Green 8pc | E7: =VLOOKUP(B7,Table3[[#Headers],[#Data]],5,FALSE) -> SELL0006 | F7: =VLOOKUP(E7,Table2[[#Headers],[#Data],[seller_id]:[seller_user]],2,FALSE) -> toysyay | G7: 1 | H7: =G7*C7 -> 38.25
A8: =VLOOKUP(B8,Table3[[#Headers],[#Data]],3,FALSE) -> Clothes | B8: PROD00010 | C8: =VLOOKUP(B8,Table3[[#Headers],[#Data]],4, FALSE) -> 30.71 | D8: =VLOOKUP('Rough data'!B8,Table3[[#Headers],[#Data]],2,FALSE) -> Summer Dress - Floral | E8: =VLOOKUP(B8,Table3[[#Headers],[#Data]],5,FALSE) -> SELL0008 | F8: =VLOOKUP(E8,Table2[[#Headers],[#Data],[seller_id]:[seller_user]],2,FALSE) -> peterpiper | G8: 1 | H8: =G8*C8 -> 30.71
A9: =VLOOKUP(B9,Table3[[#Headers],[#Data]],3,FALSE) -> Clothes | B9: PROD00010 | C9: =VLOOKUP(B9,Table3[[#Headers],[#Data]],4, FALSE) -> 30.71 | D9: =VLOOKUP('Rough data'!B9,Table3[[#Headers],[#Data]],2,FALSE) -> Summer Dress - Floral | E9: =VLOOKUP(B9,Table3[[#Headers],[#Data]],5,FALSE) -> SELL0008 | F9: =VLOOKUP(E9,Table2[[#Headers],[#Data],[seller_id]:[seller_user]],2,FALSE) -> peterpiper | G9: 1 | H9: =G9*C9 -> 30.71
A10: =VLOOKUP(B10,Table3[[#Headers],[#Data]],3,FALSE) -> Stationery | B10: PROD00012 | C10: =VLOOKUP(B10,Table3[[#Headers],[#Data]],4, FALSE) -> 7.06 | D10: =VLOOKUP('Rough data'!B10,Table3[[#Headers],[#Data]],2,FALSE) -> Whiteboard Markers - 6 pack | E10: =VLOOKUP(B10,Table3[[#Headers],[#Data]],5,FALSE) -> SELL0010 | F10: =VLOOKUP(E10,Table2[[#Headers],[#Data],[seller_id]:[seller_user]],2,FALSE) -> hobbylobby | G10: 2 | H10: =G10*C10 -> 14.12
A11: =VLOOKUP(B11,Table3[[#Headers],[#Data]],3,FALSE) -> Stationery | B11: PROD00012 | C11: =VLOOKUP(B11,Table3[[#Headers],[#Data]],4, FALSE) -> 7.06 | D11: =VLOOKUP('Rough data'!B11,Table3[[#Headers],[#Data]],2,FALSE) -> Whiteboard Markers - 6 pack | E11: =VLOOKUP(B11,Table3[[#Headers],[#Data]],5,FALSE) -> SELL0010 | F11: =VLOOKUP(E11,Table2[[#Headers],[#Data],[seller_id]:[seller_user]],2,FALSE) -> hobbylobby | G11: 2 | H11: =G11*C11 -> 14.12
A12: =VLOOKUP(B12,Table3[[#Headers],[#Data]],3,FALSE) -> Health | B12: PROD00013 | C12: =VLOOKUP(B12,Table3[[#Headers],[#Data]],4, FALSE) -> 37.4 | D12: =VLOOKUP('Rough data'!B12,Table3[[#Headers],[#Data]],2,FALSE) -> Heat Therapy Pad | E12: =VLOOKUP(B12,Table3[[#Headers],[#Data]],5,FALSE) -> SELL0011 | F12: =VLOOKUP(E12,Table2[[#Headers],[#Data],[seller_id]:[seller_user]],2,FALSE) -> dr-green | G12: 2 | H12: =G12*C12 -> 74.8
A13: =VLOOKUP(B13,Table3[[#Headers],[#Data]],3,FALSE) -> Outdoor | B13: PROD00014 | C13: =VLOOKUP(B13,Table3[[#Headers],[#Data]],4, FALSE) -> 46.45 | D13: =VLOOKUP('Rough data'!B13,Table3[[#Headers],[#Data]],2,FALSE) -> Waterproof Picnic Mat 100x100 | E13: =VLOOKUP(B13,Table3[[#Headers],[#Data]],5,FALSE) -> SELL0012 | F13: =VLOOKUP(E13,Table2[[#Headers],[#Data],[seller_id]:[seller_user]],2,FALSE) -> jane-outside | G13: 1 | H13: =G13*C13 -> 46.45
... A796: =VLOOKUP(B796,Table3[[#Headers],[#Data]],3,FALSE) -> Outdoor | B796: PROD00461 | C796: =VLOOKUP(B796,Table3[[#Headers],[#Data]],4, FALSE) -> 21 | D796: =VLOOKUP('Rough data'!B796,Table3[[#Headers],[#Data]],2,FALSE) -> Wooden Train Set | E796: =VLOOKUP(B796,Table3[[#Headers],[#Data]],5,FALSE) -> SELL0047 | F796: =VLOOKUP(E796,Table2[[#Headers],[#Data],[seller_id]:[seller_user]],2,FALSE) -> toymajoy | G796: 1 | H796: =G796*C796 -> 21

Sheet PT FOR Q3
D1: product_name | E1: Sum of product_revenue | G1: seller_user | H1: Sum of product_revenue | J1: seller_user | K1: Sum of product_quantity
D2: Adjustable Dumbbell 10kg | E2: 116.75 | G2: 1bt8plshsf | H2: 339.42 | J2: 1bt8plshsf | K2: 5
A3: product_category | B3: Sum of product_revenue | D3: Adjustable Dumbbell 12kg | E3: 182.58 | G3: 3n2ybcn0e4 | H3: 16.11 | J3: 3n2ybcn0e4 | K3: 1
A4: Beauty | B4: 1239.08 | D4: Adjustable Dumbbell 15kg | E4: 257.82 | G4: 7e16xoz37j | H4: 146.81 | J4: 7e16xoz37j | K4: 4
A5: Clothes | B5: 3487.24 | D5: Adjustable Dumbbell 20kg | E5: 77.97 | G5: 7ti9lfa6h5 | H5: 2038.12 | J5: 7ti9lfa6h5 | K5: 49
A6: Electronics | B6: 4385.23 | D6: Adjustable Dumbbell 25kg | E6: 60.93 | G6: abracadabra_002 | H6: 514.92 | J6: abracadabra_002 | K6: 26
A7: Gift_Sets | B7: 1807.1 | D7: Adjustable Dumbbell 8kg | E7: 75.4 | G7: au6ynzdcy5 | H7: 713.98 | J7: au6ynzdcy5 | K7: 14
A8: Health | B8: 2178.86 | D8: Aloe Vera Gel 150ml 2 pack | E8: 53 | G8: b8iv8o4c65 | H8: 133.02 | J8: b8iv8o4c65 | K8: 3
A9: Home | B9: 6457.93 | D9: Aloe Vera Gel 200ml | E9: 13.82 | G9: barbievend | H9: 82.71 | J9: barbievend | K9: 2
A10: Jewellery | B10: 1829.68 | D10: Aloe Vera Gel 200ml 2 pack | E10: 38.74 | G10: beautifullhome | H10: 1634.81 | J10: beautifullhome | K10: 27
A11: Outdoor | B11: 16526.25 | D11: Aloe Vera Gel 500ml | E11: 53.49 | G11: beautifullife472 | H11: 275.93 | J11: beautifullife472 | K11: 10
A12: Stationery | B12: 351.23 | D12: Anklet - Gold | E12: 13.95 | G12: beauty490 | H12: 653.91 | J12: beauty490 | K12: 14
A13: Toys | B13: 1434.61 | D13: Anklet - Silver Tone | E13: 75.52 | G13: beauty4everyone | H13: 111.68 | J13: beauty4everyone | K13: 4
A14: Grand Total | B14: 39697.21 | D14: antique bronze necklace owl vintage | E14: 49.4 | G14: blessedforall | H14: 135.96 | J14: blessedforall | K14: 7
D15: Baby Shower Gift Bundle (Blue) | E15: 32.89 | G15: bootsandcamping | H15: 135.45 | J15: bootsandcamping | K15: 9
D16: Baby Shower Gift Bundle (Yellow) | E16: 32.99 | G16: brizzy_bonanza_48 | H16: 539.25 | J16: brizzy_bonanza_48 | K16: 13
D17: Ballpoint pen 6 pack | E17: 8.72 | G17: buildmydream | H17: 487.35 | J17: buildmydream | K17: 8
D18: Bamboo Picnic Rug Recycled Material | E18: 201.4 | G18: buydongxi25 | H18: 119.5 | J18: buydongxi25 | K18: 5
D19: Bath Bomb Strawberry Vanilla Gift Set | E19: 189.2 | G19: buyeverything-1 | H19: 374.01 | J19: buyeverything-1 | K19: 6
D20: Bath Bomb Variety Pack (Rose lavender) | E20: 13.54 | G20: buyingtime | H20: 70.17 | J20: buyingtime | K20: 6
D21: Bath Bomb Variety Pack (Ylang ylang jasmine) | E21: 39.85 | G21: cheapandgood27 | H21: 334.19 | J21: cheapandgood27 | K21: 13
D22: BBQ - Charcoal | E22: 450.6 | G22: cleaning_out_my_shed | H22: 720.73 | J22: cleaning_out_my_shed | K22: 18
D23: BBQ Apron - Blue | E23: 560.49 | G23: clothes832 | H23: 108.34 | J23: clothes832 | K23: 2
D24: BBQ Apron - Red | E24: 291.51 | G24: clothesforlife | H24: 1075.58 | J24: clothesforlife | K24: 29
D25: BBQ Cleaning Brush | E25: 464.25 | G25: compradadonut | H25: 437.84 | J25: compradadonut | K25: 8
D26: BBQ Cleaning Brush XXL | E26: 363.95 | G26: cpghfp370y | H26: 24.72 | J26: cpghfp370y | K26: 4
... D88: Face mask peel-off orange 3 pack | E88: 50 | G88: zmkizlf6t6 | H88: 808.1 | J88: zmkizlf6t6 | K88: 23
D89: Face Mist Vitamin E | E89: 69.12 | G89: (blank) | J89: (blank)
D90: Fairy Lights Outdoor Garden String 100 | E90: 460.68 | G90: Grand Total | H90: 39697.21 | J90: Grand Total | K90: 940
D91: Fairy Lights Outdoor Garden String 200 | E91: 111.78
D92: Floor Lamp Standing Tall LED | E92: 248.64
D93: Foam Maker | E93: 37.98
D94: Foam Roller - Firm Black | E94: 43.01
D95: Foam Roller - Firm Blue Large | E95: 98.42
D96: Fruity Mango Bath Gel Gift Set | E96: 72.78
D97: Gaming Mouse | E97: 53.16
D98: Garden Hose 20m (Green) | E98: 57.98
D99: Garden Hose 20m (Grey) | E99: 167.97
D100: Garden Hose 50m (Green) | E100: 262.53
D101: Garden Hose 50m (Grey) | E101: 96.77
...

Sheet sellers_2026
A1: seller_id | B1: seller_user | C1: seller_name | D1: seller_surname | E1: seller_email | F1: seller_area | G1: seller_state
A2: SELL0001 | B2: beauty4everyone | C2: Mariah | D2: Davila | E2: mdavila8@gmail.com | F2: Cloncurry | G2: VIC | I2: Row Labels | J2: Count of seller_id
A3: SELL0002 | B3: wan-yifu | C3: Li | D3: Mei | E3: lmei@hotmail.com | F3: Adelaide | G3: SA | I3: ACT | J3: 8
A4: SELL0003 | B4: electroshop | C4: Persephone | D4: Horne | E4: electroshop@aol.com | F4: Albany | G4: WA | I4: NSW | J4: 10
A5: SELL0004 | B5: nol6svwlnf | C5: Zee | D5: Dodson | E5: nol6svwlnf@optusnet.com.au | F5: Gawler | G5: SA | I5: NT | J5: 13
A6: SELL0005 | B6: pensandthings | C6: Etta | D6: Conway | E6: ett-conway72@gmail.com | F6: Launceston | G6: TAS | I6: QLD | J6: 15
A7: SELL0006 | B7: toysyay | C7: Oliver | D7: Flowers | E7: oflowers7@microsoft.com | F7: Bendigo | G7: VIC | I7: SA | J7: 7
A8: SELL0007 | B8: healthy_habits | C8: Ariya | D8: Harmon | E8: healthy_habits@gmail.com | F8: Townsville | G8: QLD | I8: TAS | J8: 13
A9: SELL0008 | B9: peterpiper | C9: Peter | D9: Stafford | E9: peter-stafford1982@gmail.com | F9: Winton | G9: QLD | I9: VIC | J9: 19
A10: SELL0009 | B10: bootsandcamping | C10: Bridget | D10: Fisher | E10: bridget_fisher@microsoft.com | F10: Toowoomba | G10: QLD | I10: WA | J10: 10
A11: SELL0010 | B11: hobbylobby | C11: Gordon | D11: O'Flannagan | E11: hobbylobby@microsoft.com | F11: Melbourne | G11: VIC | I11: (blank)
A12: SELL0011 | B12: dr-green | C12: Giuliana | D12: Green | E12: ggreen@optusnet.com.au | F12: Brisbane | G12: QLD | I12: Grand Total | J12: 95
A13: SELL0012 | B13: jane-outside | C13: Jane | D13: Little | E13: jane-little@gmail.com | F13: Kalgoorlie | G13: WA
A14: SELL0013 | B14: slln3xj7zl | C14: Alice | D14: Daniels | E14: alidaniels58@gmail.com | F14: Adelaide | G14: SA
A15: SELL0014 | B15: gardenandco | C15: Xander | D15: Lester | E15: xlester@hotmail.com | F15: Canberra | G15: ACT
A16: SELL0015 | B16: outhomelovely | C16: Averi | D16: Glenn | E16: aglenn@hotmail.com | F16: Newcastle | G16: NSW
A17: SELL0016 | B17: abracadabra_002 | C17: Zaid | D17: Blake | E17: zaid-blake@gmail.com | F17: Strahan | G17: TAS
A18: SELL0017 | B18: 7e16xoz37j | C18: Amanda | D18: Doyle | E18: adoyle8@live.au | F18: Rockhampton | G18: QLD
A19: SELL0018 | B19: darwin_beauty | C19: Karly | D19: Bowers | E19: k.bowers@gmail.com | F19: Darwin | G19: NT
A20: SELL0019 | B20: buyingtime | C20: Elisa | D20: Foster | E20: elisa_foster1993@gmail.com | F20: Mareeba | G20: QLD
A21: SELL0020 | B21: staion-bonanza | C21: Christian | D21: Mcdonald | E21: staion-bonanza@hotmail.com | F21: Darwin | G21: NT
A22: SELL0021 | B22: stuff-on-sale | C22: Daisy | D22: Cano | E22: dcano@hotmail.com | F22: Melbourne | G22: VIC
A23: SELL0022 | B23: g5x9v55sct | C23: Terry | D23: Gibbs | E23: tgibbs5@microsoft.com | F23: Bunbury | G23: WA
A24: SELL0023 | B24: cleaning_out_my_shed | C24: Colin | D24: Curry | E24: c.curry@gmail.com | F24: Bendigo | G24: VIC
... A96: SELL0095 | B96: toybuy | C96: Benji | D96: Lang | E96: blang@hotmail.com | F96: Port Lincoln | G96: TAS

Sheet customers
A1: customer_id | B1: customer_email | C1: customer_name | D1: customer_surname | E1: customer_area | F1: customer_state | G1: total_customer_spend | H1: number_of_orders | I1: Customer_type
A2: CUST00001 | B2: freya95@bigpond.com.au | C2: Freya | D2: Adams | E2: Darwin | F2: NT | G2: =SUMIF(orders!B:B,A2,orders!F:F) -> 0 | H2: =COUNTIF(orders!B:B,A2) -> 0 | I2: =IF(H2>1,"Repeat Customer","One-Time Customer") -> One-Time Customer
A3: CUST00002 | B3: charliesat@bigpond.com.au | C3: Charles | D3: Sato | E3: Central Coast | F3: NSW | G3: =SUMIF(orders!B:B,A3,orders!F:F) -> 0 | H3: =COUNTIF(orders!B:B,A3) -> 0 | I3: =IF(H3>1,"Repeat Customer","One-Time Customer") -> One-Time Customer
A4: CUST00003 | B4: jack26@gmail.com | C4: Jack | D4: Petrov | E4: Ballarat | F4: VIC | G4: =SUMIF(orders!B:B,A4,orders!F:F) -> 430.15 | H4: =COUNTIF(orders!B:B,A4) -> 3 | I4: =IF(H4>1,"Repeat Customer","One-Time Customer") -> Repeat Customer | M4: Row Labels | N4: Count of customer_id | O4: visual 1 customers by state
A5: CUST00004 | B5: footy.minh@live.au | C5: Minh | D5: Pham | E5: Broken Hill | F5: NSW | G5: =SUMIF(orders!B:B,A5,orders!F:F) -> 70.83 | H5: =COUNTIF(orders!B:B,A5) -> 2 | I5: =IF(H5>1,"Repeat Customer","One-Time Customer") -> Repeat Customer | M5: ACT | N5: 4
A6: CUST00005 | B6: bianchi.aurora@outlook.com | C6: Aurora | D6: Bianchi | E6: Kalgoorlie | F6: WA | G6: =SUMIF(orders!B:B,A6,orders!F:F) -> 49.22 | H6: =COUNTIF(orders!B:B,A6) -> 2 | I6: =IF(H6>1,"Repeat Customer","One-Time Customer") -> Repeat Customer | M6: NSW | N6: 141 | O6: NSW is CompradaRoo's largest customer market, accounting for approximately 32% of all customers (141 of 441).
A7: CUST00006 | B7: noah.jameson@outlook.com | C7: Noah | D7: Jameson | E7: Coffs Harbour | F7: NSW | G7: =SUMIF(orders!B:B,A7,orders!F:F) -> 418.57 | H7: =COUNTIF(orders!B:B,A7) -> 7 | I7: =IF(H7>1,"Repeat Customer","One-Time Customer") -> Repeat Customer | M7: NT | N7: 5
A8: CUST00007 | B8: lucas1997@bigpond.com.au | C8: Luca | D8: Gomez | E8: Townsville | F8: QLD | G8: =SUMIF(orders!B:B,A8,orders!F:F) -> 29.85 | H8: =COUNTIF(orders!B:B,A8) -> 1 | I8: =IF(H8>1,"Repeat Customer","One-Time Customer") -> One-Time Customer | M8: QLD | N8: 96
A9: CUST00008 | B9: tanaka.sienna@outlook.com | C9: Sienna | D9: Tanaka | E9: Sydney | F9: NSW | G9: =SUMIF(orders!B:B,A9,orders!F:F) -> 56.31 | H9: =COUNTIF(orders!B:B,A9) -> 2 | I9: =IF(H9>1,"Repeat Customer","One-Time Customer") -> Repeat Customer | M9: SA | N9: 26
A10: CUST00009 | B10: urbanedward@microsoft.com | C10: Edward | D10: Silver | E10: Dubbo | F10: NSW | G10: =SUMIF(orders!B:B,A10,orders!F:F) -> 0 | H10: =COUNTIF(orders!B:B,A10) -> 0 | I10: =IF(H10>1,"Repeat Customer","One-Time Customer") -> One-Time Customer | M10: TAS | N10: 14
A11: CUST00010 | B11: turner.hiro@gmail.com | C11: Hiro | D11: Turner | E11: Hervey Bay | F11: QLD | G11: =SUMIF(orders!B:B,A11,orders!F:F) -> 727.08 | H11: =COUNTIF(orders!B:B,A11) -> 6 | I11: =IF(H11>1,"Repeat Customer","One-Time Customer") -> Repeat Customer | M11: VIC | N11: 109
A12: CUST00011 | B12: lucas.deluca@outlook.com | C12: Lindsay | D12: DeLuca | E12: Sydney | F12: NSW | G12: =SUMIF(orders!B:B,A12,orders!F:F) -> 340.97 | H12: =COUNTIF(orders!B:B,A12) -> 4 | I12: =IF(H12>1,"Repeat Customer","One-Time Customer") -> Repeat Customer | M12: WA | N12: 46
A13: CUST00012 | B13: charliecharliecharlie@outlook.com | C13: Charlotte | D13: Walker | E13: Bendigo | F13: VIC | G13: =SUMIF(orders!B:B,A13,orders!F:F) -> 139.02 | H13: =COUNTIF(orders!B:B,A13) -> 2 | I13: =IF(H13>1,"Repeat Customer","One-Time Customer") -> Repeat Customer | M13: Grand Total | N13: 441
A14: CUST00013 | B14: coffee.tom@gmail.com | C14: Thomas | D14: Ngata | E14: Dubbo | F14: NSW | G14: =SUMIF(orders!B:B,A14,orders!F:F) -> 114.29 | H14: =COUNTIF(orders!B:B,A14) -> 2 | I14: =IF(H14>1,"Repeat Customer","One-Time Customer") -> Repeat Customer
A15: CUST00014 | B15: latelucas@optusnet.com.au | C15: Lucas | D15: Faatua | E15: Coffs Harbour | F15: NSW | G15: =SUMIF(orders!B:B,A15,orders!F:F) -> 145.38 | H15: =COUNTIF(orders!B:B,A15) -> 2 | I15: =IF(H15>1,"Repeat Customer","One-Time Customer") -> Repeat Customer
A16: CUST00015 | B16: tom_684@microsoft.com | C16: Thomas | D16: Green | E16: Brisbane | F16: QLD | G16: =SUMIF(orders!B:B,A16,orders!F:F) -> 312.39 | H16: =COUNTIF(orders!B:B,A16) -> 5 | I16: =IF(H16>1,"Repeat Customer","One-Time Customer") -> Repeat Customer
A17: CUST00016 | B17: aaarav@gmail.com | C17: Aarav | D17: Costa | E17: Cairns | F17: QLD | G17: =SUMIF(orders!B:B,A17,orders!F:F) -> 46.28 | H17: =COUNTIF(orders!B:B,A17) -> 1 | I17: =IF(H17>1,"Repeat Customer","One-Time Customer") -> One-Time Customer
A18: CUST00017 | B18: redpoppy2574@aol.com | C18: Poppy | D18: Liu | E18: Darwin | F18: NT | G18: =SUMIF(orders!B:B,A18,orders!F:F) -> 161.5 | H18: =COUNTIF(orders!B:B,A18) -> 4 | I18: =IF(H18>1,"Repeat Customer","One-Time Customer") -> Repeat Customer
A19: CUST00018 | B19: sophie83@gmail.com | C19: Sophy | D19: Ali | E19: Port Lincoln | F19: SA | G19: =SUMIF(orders!B:B,A19,orders!F:F) -> 112.68 | H19: =COUNTIF(orders!B:B,A19) -> 3 | I19: =IF(H19>1,"Repeat Customer","One-Time Customer") -> Repeat Customer
A20: CUST00019 | B20: thuy.travel@live.au | C20: Thuy | D20: Anderson | E20: Adelaide | F20: SA | G20: =SUMIF(orders!B:B,A20,orders!F:F) -> 0 | H20: =COUNTIF(orders!B:B,A20) -> 0 | I20: =IF(H20>1,"Repeat Customer","One-Time Customer") -> One-Time Customer
A21: CUST00020 | B21: wturner@microsoft.com | C21: Willow | D21: Turner | E21: Geelong | F21: VIC | G21: =SUMIF(orders!B:B,A21,orders!F:F) -> 0 | H21: =COUNTIF(orders!B:B,A21) -> 0 | I21: =IF(H21>1,"Repeat Customer","One-Time Customer") -> One-Time Customer
A22: CUST00021 | B22: luna.footy@hotmail.com | C22: Luna | D22: Lee | E22: Coffs Harbour | F22: NSW | G22: =SUMIF(orders!B:B,A22,orders!F:F) -> 0 | H22: =COUNTIF(orders!B:B,A22) -> 0 | I22: =IF(H22>1,"Repeat Customer","One-Time Customer") -> One-Time Customer | M22: customer_state | N22: Sum of total_customer_spend | O22: visual 2 revenue by state
A23: CUST00022 | B23: oliver.liu@gmail.com | C23: Oliver | D23: Liu | E23: Brisbane | F23: QLD | G23: =SUMIF(orders!B:B,A23,orders!F:F) -> 304.61 | H23: =COUNTIF(orders!B:B,A23) -> 2 | I23: =IF(H23>1,"Repeat Customer","One-Time Customer") -> Repeat Customer | M23: ACT | N23: 356.67
A24: CUST00023 | B24: matildaanderson@optusnet.com.au | C24: Matilda | D24: Anderson | E24: Perth | F24: WA | G24: =SUMIF(orders!B:B,A24,orders!F:F) -> 45.71 | H24: =COUNTIF(orders!B:B,A24) -> 1 | I24: =IF(H24>1,"Repeat Customer","One-Time Customer") -> One-Time Customer | M24: NSW | N24: 12338.55 | O24: NSW generates the highest customer revenue, contributing around one-third of total platform revenue.
A25: CUST00024 | B25: anguswild@hotmail.com | C25: Andie | D25: Kitt | E25: Melbourne | F25: VIC | G25: =SUMIF(orders!B:B,A25,orders!F:F) -> 26.37 | H25: =COUNTIF(orders!B:B,A25) -> 1 | I25: =IF(H25>1,"Repeat Customer","One-Time Customer") -> One-Time Customer | M25: NT | N25: 272.25
A26: CUST00025 | B26: brown.ava@aol.com | C26: Ava | D26: Brown | E26: Sydney | F26: NSW | G26: =SUMIF(orders!B:B,A26,orders!F:F) -> 129.4 | H26: =COUNTIF(orders!B:B,A26) -> 4 | I26: =IF(H26>1,"Repeat Customer","One-Time Customer") -> Repeat Customer | M26: QLD | N26: 8255.85
A27: CUST00026 | B27: art.aurora@gmail.com | C27: Anya | D27: Kaur | E27: Newcastle | F27: NSW | G27: =SUMIF(orders!B:B,A27,orders!F:F) -> 63.26 | H27: =COUNTIF(orders!B:B,A27) -> 2 | I27: =IF(H27>1,"Repeat Customer","One-Time Customer") -> Repeat Customer | M27: SA | N27: 1987.83
A28: CUST00027 | B28: mason.murphy@hotmail.com | C28: Mason | D28: Murphy | E28: Byron Bay | F28: NSW | G28: =SUMIF(orders!B:B,A28,orders!F:F) -> 194.69 | H28: =COUNTIF(orders!B:B,A28) -> 2 | I28: =IF(H28>1,"Repeat Customer","One-Time Customer") -> Repeat Customer | M28: TAS | N28: 1161.99
A29: CUST00028 | B29: zoerossi@yahoo.com | C29: Zoe | D29: Rossi | E29: Sydney | F29: NSW | G29: =SUMIF(orders!B:B,A29,orders!F:F) -> 590.89 | H29: =COUNTIF(orders!B:B,A29) -> 7 | I29: =IF(H29>1,"Repeat Customer","One-Time Customer") -> Repeat Customer | M29: VIC | N29: 9985.15
A30: CUST00029 | B30: pham.amelia@hotmail.com | C30: Amelia | D30: Pham | E30: Bunbury | F30: WA | G30: =SUMIF(orders!B:B,A30,orders!F:F) -> 217.01 | H30: =COUNTIF(orders!B:B,A30) -> 3 | I30: =IF(H30>1,"Repeat Customer","One-Time Customer") -> Repeat Customer | M30: WA | N30: 3465.25
A31: CUST00030 | B31: photo.amelia@gmail.com | C31: Amelia | D31: Wilson | E31: Shepparton | F31: VIC | G31: =SUMIF(orders!B:B,A31,orders!F:F) -> 50.71 | H31: =COUNTIF(orders!B:B,A31) -> 1 | I31: =IF(H31>1,"Repeat Customer","One-Time Customer") -> One-Time Customer | M31: Grand Total | N31: 37823.54
A32: CUST00031 | B32: leebrrown@optusnet.com.au | C32: Lee | D32: Brown | E32: Sydney | F32: NSW | G32: =SUMIF(orders!B:B,A32,orders!F:F) -> 270.6 | H32: =COUNTIF(orders!B:B,A32) -> 4 | I32: =IF(H32>1,"Repeat Customer","One-Time Customer") -> Repeat Customer
A33: CUST00032 | B33: ekhan@yahoo.com | C33: Edward | D33: Khan | E33: Melbourne | F33: VIC | G33: =SUMIF(orders!B:B,A33,orders!F:F) -> 219.63 | H33: =COUNTIF(orders!B:B,A33) -> 2 | I33: =IF(H33>1,"Repeat Customer","One-Time Customer") -> Repeat Customer
A34: CUST00033 | B34: luiswild@gmail.com | C34: Luis | D34: Clerk | E34: Wagga Wagga | F34: NSW | G34: =SUMIF(orders!B:B,A34,orders!F:F) -> 190.95 | H34: =COUNTIF(orders!B:B,A34) -> 3 | I34: =IF(H34>1,"Repeat Customer","One-Time Customer") -> Repeat Customer
A35: CUST00034 | B35: sadie_153@microsoft.com | C35: Sadie | D35: Chen | E35: Rockhampton | F35: QLD | G35: =SUMIF(orders!B:B,A35,orders!F:F) -> 196.22 | H35: =COUNTIF(orders!B:B,A35) -> 2 | I35: =IF(H35>1,"Repeat Customer","One-Time Customer") -> Repeat Customer
A36: CUST00035 | B36: parks.sandy@gmail.com | C36: Sandy | D36: Parks | E36: Brisbane | F36: QLD | G36: =SUMIF(orders!B:B,A36,orders!F:F) -> 58.42 | H36: =COUNTIF(orders!B:B,A36) -> 1 | I36: =IF(H36>1,"Repeat Customer","One-Time Customer") -> One-Time Customer
A37: CUST00036 | B37: carls@outlook.com | C37: Carl | D37: Stewart | E37: Ballarat | F37: VIC | G37: =SUMIF(orders!B:B,A37,orders!F:F) -> 285.64 | H37: =COUNTIF(orders!B:B,A37) -> 3 | I37: =IF(H37>1,"Repeat Customer","One-Time Customer") -> Repeat Customer
A38: CUST00037 | B38: sienna_825@live.au | C38: Emma | D38: Papadopoulos | E38: Warrnambool | F38: VIC | G38: =SUMIF(orders!B:B,A38,orders!F:F) -> 343.41 | H38: =COUNTIF(orders!B:B,A38) -> 2 | I38: =IF(H38>1,"Repeat Customer","One-Time Customer") -> Repeat Customer
A39: CUST00038 | B39: grace_748@hotmail.com | C39: Grace | D39: Liu | E39: Brisbane | F39: QLD | G39: =SUMIF(orders!B:B,A39,orders!F:F) -> 0 | H39: =COUNTIF(orders!B:B,A39) -> 0 | I39: =IF(H39>1,"Repeat Customer","One-Time Customer") -> One-Time Customer
A40: CUST00039 | B40: ethan.turner@live.au | C40: Ethan | D40: Turner | E40: Rockhampton | F40: QLD | G40: =SUMIF(orders!B:B,A40,orders!F:F) -> 0 | H40: =COUNTIF(orders!B:B,A40) -> 0 | I40: =IF(H40>1,"Repeat Customer","One-Time Customer") -> One-Time Customer | M40: Row Labels | N40: Sum of total_customer_spend | O40: visual 3 repeat vsone time customers
...

Sheet orders
A1: order_id | B1: customer_id | C1: order_date | D1: delivery_est | E1: delivery_date | F1: order_total_aud | G1: delivery_delay | H1: Delivery_time_all | I1: Delay (-)/On time (+)_all
A2: ORD000001 | B2: CUST00004 | C2: 45322.508 | D2: 45333 | E2: 45333.673 | F2: 18.74 | G2: =INT(E2)-INT(D2) -> 0 | H2: 11.16515 | I2: -0.67280093 | L2: =SUM(F2:F166) -> 12430.73 | M2: =SUM(N267) -> 0
A3: ORD000002 | B3: CUST00005 | C3: 45323.16 | D3: 45329 | E3: 45329.696 | F3: 35.97 | G3: =INT(E3)-INT(D3) -> 0 | H3: 6.5360417 | I3: -0.69615741
A4: ORD000003 | B4: CUST00011 | C4: 45342.849 | D4: 45347 | E4: 45347.548 | F4: 23.96 | G4: =INT(E4)-INT(D4) -> 0 | H4: 4.6990046 | I4: -0.54798611
A5: ORD000004 | B5: CUST00015 | C5: 45355.067 | D5: 45359 | E5: 45361.396 | F5: 36.25 | G5: =INT(E5)-INT(D5) -> 2 | H5: 6.329375 | I5: -2.3961921
A6: ORD000005 | B6: CUST00017 | C6: 45356.483 | D6: 45358 | E6: 45358.605 | F6: 7.18 | G6: =INT(E6)-INT(D6) -> 0 | H6: 2.1217361 | I6: -0.6046412
A7: ORD000006 | B7: CUST00016 | C7: 45358.174 | D7: 45363 | E7: 45363.656 | F7: 46.28 | G7: =INT(E7)-INT(D7) -> 0 | H7: 5.4815394 | I7: -0.65565972
A8: ORD000007 | B8: CUST00018 | C8: 45363.414 | D8: 45367 | E8: 45367.344 | F8: 31.78 | G8: =INT(E8)-INT(D8) -> 0 | H8: 3.9304745 | I8: -0.34443287
A9: ORD000008 | B9: CUST00022 | C9: 45376.197 | D9: 45381 | E9: 45382.512 | F9: 20.2 | G9: =INT(E9)-INT(D9) -> 1 | H9: 6.3154514 | I9: -1.5124074
A10: ORD000009 | B10: CUST00024 | C10: 45378.181 | D10: 45386 | E10: 45386.642 | F10: 26.37 | G10: =INT(E10)-INT(D10) -> 0 | H10: 8.4615856 | I10: -0.64234954
A11: ORD000010 | B11: CUST00028 | C11: 45384.319 | D11: 45389 | E11: 45389.655 | F11: 45.78 | G11: =INT(E11)-INT(D11) -> 0 | H11: 5.3359606 | I11: -0.65525463
A12: ORD000011 | B12: CUST00029 | C12: 45385.5 | D12: 45393 | E12: 45391.604 | F12: 104.6 | G12: =INT(E12)-INT(D12) -> -2 | H12: 6.1044444 | I12: 1.3960069
A13: ORD000012 | B13: CUST00025 | C13: 45387.401 | D13: 45397 | E13: 45396.668 | F13: 48.67 | G13: =INT(E13)-INT(D13) -> -1 | H13: 9.267037 | I13: 0.33194444
A14: ORD000013 | B14: CUST00034 | C14: 45388.231 | D14: 45392 | E14: 45391.5 | F14: 37.94 | G14: =INT(E14)-INT(D14) -> -1 | H14: 3.2688657 | I14: 0.50025463
... A48: ORD000047 | B48: CUST00115 | C48: 45448.593 | D48: 45456 | E48: 45456.378 | F48: 37.81 | G48: =INT(E48)-INT(D48) -> 0 | H48: 7.7851389 | I48: -0.37793982
A49: ORD000048 | B49: CUST00117 | C49: 45449.566 | D49: 45455 | E49: 45456.517 | F49: 70.28 | G49: =INT(E49)-INT(D49) -> 1 | H49: 6.9510185 | I49: -1.5169907 | P49: =SUM(F2:F479) -> 37823.54
A50: ORD000049 | B50: CUST00119 | C50: 45450.026 | D50: 45454 | E50: 45457.595 | F50: 10.02 | G50: =INT(E50)-INT(D50) -> 3 | H50: 7.5689005 | I50: -3.5948727
A51: ORD000050 | B51: CUST00120 | C51: 45450.611 | D51: 45455 | E51: 45454.74 | F51: 37.43 | G51: =INT(E51)-INT(D51) -> -1 | H51: 4.129294 | I51: 0.25986111
A52: ORD000051 | B52: CUST00121 | C52: 45452.31 | D52: 45460 | E52: 45459.485 | F52: 119.27 | G52: =INT(E52)-INT(D52) -> -1 | H52: 7.1742014 | I52: 0.51542824
A53: ORD000052 | B53: CUST00028 | C53: 45452.406 | D53: 45462 | E53: 45464.64 | F53: 16.14 | G53: =INT(E53)-INT(D53) -> 2 | H53: 12.233808 | I53: -2.639537
A54: ORD000053 | B54: CUST00124 | C54: 45453.395 | D54: 45463 | E54: 45464.685 | F54: 46.84 | G54: =INT(E54)-INT(D54) -> 1 | H54: 11.289687 | I54: -1.6849884
A55: ORD000054 | B55: CUST00130 | C55: 45458.6 | D55: 45467 | E55: 45466.363 | F55: 4.94 | G55: =INT(E55)-INT(D55) -> -1 | H55: 7.7630556 | I55: 0.63741898
A56: ORD000055 | B56: CUST00131 | C56: 45458.936 | D56: 45466 | E56: 45466.455 | F56: 126.9 | G56: =INT(E56)-INT(D56) -> 0 | H56: 7.5184722 | I56: -0.45475694
A57: ORD000056 | B57: CUST00132 | C57: 45458.954 | D57: 45465 | E57: 45467.545 | F57: 155.05 | G57: =INT(E57)-INT(D57) -> 2 | H57: 8.5906134 | I57: -2.5445602
A58: ORD000057 | B58: CUST00133 | C58: 45460.714 | D58: 45467 | E58: 45467.606 | F58: 117.5 | G58: =INT(E58)-INT(D58) -> 0 | H58: 6.8927083 | I58: -0.60638889
A59: ORD000058 | B59: CUST00137 | C59: 45462.761 | D59: 45467 | E59: 45467.646 | F59: 18.99 | G59: =INT(E59)-INT(D59) -> 0 | H59: 4.8852778 | I59: -0.64601852
A60: ORD000059 | B60: CUST00089 | C60: 45463.543 | D60: 45473 | E60: 45474.636 | F60: 85.13 | G60: =INT(E60)-INT(D60) -> 1 | H60: 11.092778 | I60: -1.6360069
A61: ORD000060 | B61: CUST00138 | C61: 45464.223 | D61: 45471 | E61: 45472.663 | F61: 86.28 | G61: =INT(E61)-INT(D61) -> 1 | H61: 8.4403819 | I61: -1.6633796
... A134: ORD000133 | B134: CUST00233 | C134: 45634.624 | D134: 45639 | E134: 45641.511 | F134: 23.12 | G134: =INT(E134)-INT(D134) -> 2 | H134: 6.8870139 | I134: -2.5113657
A135: ORD000134 | B135: CUST00011 | C135: 45635.1 | D135: 45643 | E135: 45643.667 | F135: 105.72 | G135: =INT(E135)-INT(D135) -> 0 | H135: 8.5672685 | I135: -0.66737269 | L135: =AVERAGE(F2:F166) -> 75.337758
A136: ORD000135 | B136: CUST00235 | C136: 45635.411 | D136: 45641 | E136: 45641.44 | F136: 63.79 | G136: =INT(E136)-INT(D136) -> 0 | H136: 6.0287153 | I136: -0.44009259
A137: ORD000136 | B137: CUST00202 | C137: 45635.542 | D137: 45642 | E137: 45643.444 | F137: 171.34 | G137: =INT(E137)-INT(D137) -> 1 | H137: 7.9027778 | I137: -1.4444329 | L137: avergae of 25
A138: ORD000137 | B138: CUST00237 | C138: 45637.409 | D138: 45642 | E138: 45644.353 | F138: 80.95 | G138: =INT(E138)-INT(D138) -> 2 | H138: 6.9446065 | I138: -2.3531944
A139: ORD000138 | B139: CUST00240 | C139: 45638.015 | D139: 45644 | E139: 45644.719 | F139: 97.18 | G139: =INT(E139)-INT(D139) -> 0 | H139: 6.7041782 | I139: -0.71912037
A140: ORD000139 | B140: CUST00242 | C140: 45638.34 | D140: 45643 | E140: 45643.424 | F140: 27.18 | G140: =INT(E140)-INT(D140) -> 0 | H140: 5.0832523 | I140: -0.42366898
A141: ORD000140 | B141: CUST00241 | C141: 45638.611 | D141: 45644 | E141: 45644.453 | F141: 91.22 | G141: =INT(E141)-INT(D141) -> 0 | H141: 5.8422917 | I141: -0.45326389
A142: ORD000141 | B142: CUST00081 | C142: 45639.339 | D142: 45643 | E142: 45642.667 | F142: 53.83 | G142: =INT(E142)-INT(D142) -> -1 | H142: 3.3281481 | I142: 0.33284722
A143: ORD000142 | B143: CUST00170 | C143: 45639.975 | D143: 45644 | E143: 45644.423 | F143: 50.45 | G143: =INT(E143)-INT(D143) -> 0 | H143: 4.4484722 | I143: -0.42299769
A144: ORD000143 | B144: CUST00240 | C144: 45642.911 | D144: 45649 | E144: 45648.736 | F144: 78.15 | G144: =INT(E144)-INT(D144) -> -1 | H144: 5.8254745 | I144: 0.26383102
A145: ORD000144 | B145: CUST00037 | C145: 45642.931 | D145: 45649 | E145: 45653.385 | F145: 232.38 | G145: =INT(E145)-INT(D145) -> 4 | H145: 10.453403 | I145: -4.3846065
...

Sheet order_items
A1: order_id | B1: product_id | C1: product_quantity | D1: product_category | E1: product_price | F1: item_revenue | G1: product_name | H1: seller_id | I1: seller_state | J1: seller_user
A2: ORD000001 | B2: PROD00077 | C2: 1 | D2: =_xlfn.XLOOKUP(order_items!B2,products_2026!A:A,products_2026!C:C,,0,) -> Home | E2: =_xlfn.XLOOKUP(B2,products_2026!A:A,products_2026!D:D,,0,) -> 26.76 | F2: =C2*E2 -> 26.76 | G2: =_xlfn.XLOOKUP(B2,products_2026!A:A,products_2026!B:B,,0,) -> Scented Drawer Sachets Jasmine | H2: =_xlfn.XLOOKUP(B2,products_2026!A:A,products_2026!E:E,,0,) -> SELL0036 | I2: =IFERROR(_xlfn.XLOOKUP(H2,sellers_2026!A:A,sellers_2026!G:G,,0,), "unknown/inactive") -> NT | J2: =_xlfn.XLOOKUP(H2,sellers_2026!A:A,sellers_2026!B:B,,0,) -> goodqualityemporium
A3: ORD000002 | B3: PROD00191 | C3: 1 | D3: =_xlfn.XLOOKUP(order_items!B3,products_2026!A:A,products_2026!C:C,,0,) -> Jewellery | E3: =_xlfn.XLOOKUP(B3,products_2026!A:A,products_2026!D:D,,0,) -> 47.32 | F3: =C3*E3 -> 47.32 | G3: =_xlfn.XLOOKUP(B3,products_2026!A:A,products_2026!B:B,,0,) -> Men’s Leather Band Bracelet | H3: =_xlfn.XLOOKUP(B3,products_2026!A:A,products_2026!E:E,,0,) -> SELL0062 | I3: =IFERROR(_xlfn.XLOOKUP(H3,sellers_2026!A:A,sellers_2026!G:G,,0,), "unknown/inactive") -> QLD | J3: =_xlfn.XLOOKUP(H3,sellers_2026!A:A,sellers_2026!B:B,,0,) -> queenslandqweenie
A4: ORD000003 | B4: PROD00230 | C4: 1 | D4: =_xlfn.XLOOKUP(order_items!B4,products_2026!A:A,products_2026!C:C,,0,) -> Beauty | E4: =_xlfn.XLOOKUP(B4,products_2026!A:A,products_2026!D:D,,0,) -> 25 | F4: =C4*E4 -> 25 | G4: =_xlfn.XLOOKUP(B4,products_2026!A:A,products_2026!B:B,,0,) -> Face mask peel-off orange 3 pack | H4: =_xlfn.XLOOKUP(B4,products_2026!A:A,products_2026!E:E,,0,) -> SELL0075 | I4: =IFERROR(_xlfn.XLOOKUP(H4,sellers_2026!A:A,sellers_2026!G:G,,0,), "unknown/inactive") -> NSW | J4: =_xlfn.XLOOKUP(H4,sellers_2026!A:A,sellers_2026!B:B,,0,) -> nhlay6j49a
A5: ORD000004 | B5: PROD00204 | C5: 1 | D5: =_xlfn.XLOOKUP(order_items!B5,products_2026!A:A,products_2026!C:C,,0,) -> Electronics | E5: =_xlfn.XLOOKUP(B5,products_2026!A:A,products_2026!D:D,,0,) -> 38.56 | F5: =C5*E5 -> 38.56 | G5: =_xlfn.XLOOKUP(B5,products_2026!A:A,products_2026!B:B,,0,) -> USB C Fast Charger 30W (Black) | H5: =_xlfn.XLOOKUP(B5,products_2026!A:A,products_2026!E:E,,0,) -> SELL0067 | I5: =IFERROR(_xlfn.XLOOKUP(H5,sellers_2026!A:A,sellers_2026!G:G,,0,), "unknown/inactive") -> WA | J5: =_xlfn.XLOOKUP(H5,sellers_2026!A:A,sellers_2026!B:B,,0,) -> w71bv3mee1
A6: ORD000005 | B6: PROD00452 | C6: 1 | D6: =_xlfn.XLOOKUP(order_items!B6,products_2026!A:A,products_2026!C:C,,0,) -> Stationery | E6: =_xlfn.XLOOKUP(B6,products_2026!A:A,products_2026!D:D,,0,) -> 7.32 | F6: =C6*E6 -> 7.32 | G6: =_xlfn.XLOOKUP(B6,products_2026!A:A,products_2026!B:B,,0,) -> Gel Pen Set - 10 pack (Black) | H6: =_xlfn.XLOOKUP(B6,products_2026!A:A,products_2026!E:E,,0,) -> SELL0010 | I6: =IFERROR(_xlfn.XLOOKUP(H6,sellers_2026!A:A,sellers_2026!G:G,,0,), "unknown/inactive") -> VIC | J6: =_xlfn.XLOOKUP(H6,sellers_2026!A:A,sellers_2026!B:B,,0,) -> hobbylobby
A7: ORD000006 | B7: PROD00084 | C7: 1 | D7: =_xlfn.XLOOKUP(order_items!B7,products_2026!A:A,products_2026!C:C,,0,) -> Home | E7: =_xlfn.XLOOKUP(B7,products_2026!A:A,products_2026!D:D,,0,) -> 46.55 | F7: =C7*E7 -> 46.55 | G7: =_xlfn.XLOOKUP(B7,products_2026!A:A,products_2026!B:B,,0,) -> Stainless Steel Cutting Board | H7: =_xlfn.XLOOKUP(B7,products_2026!A:A,products_2026!E:E,,0,) -> SELL0037 | I7: =IFERROR(_xlfn.XLOOKUP(H7,sellers_2026!A:A,sellers_2026!G:G,,0,), "unknown/inactive") -> VIC | J7: =_xlfn.XLOOKUP(H7,sellers_2026!A:A,sellers_2026!B:B,,0,) -> storeshop
A8: ORD000007 | B8: PROD00283 | C8: 1 | D8: =_xlfn.XLOOKUP(order_items!B8,products_2026!A:A,products_2026!C:C,,0,) -> Clothes | E8: =_xlfn.XLOOKUP(B8,products_2026!A:A,products_2026!D:D,,0,) -> 32.76 | F8: =C8*E8 -> 32.76 | G8: =_xlfn.XLOOKUP(B8,products_2026!A:A,products_2026!B:B,,0,) -> Kids Cotton Pyjamas 6-8y | H8: =_xlfn.XLOOKUP(B8,products_2026!A:A,products_2026!E:E,,0,) -> SELL0086 | I8: =IFERROR(_xlfn.XLOOKUP(H8,sellers_2026!A:A,sellers_2026!G:G,,0,), "unknown/inactive") -> VIC | J8: =_xlfn.XLOOKUP(H8,sellers_2026!A:A,sellers_2026!B:B,,0,) -> clothesforlife | L8: Row Labels | M8: Sum of item_revenue
A9: ORD000008 | B9: PROD00081 | C9: 1 | D9: =_xlfn.XLOOKUP(order_items!B9,products_2026!A:A,products_2026!C:C,,0,) -> Jewellery | E9: =_xlfn.XLOOKUP(B9,products_2026!A:A,products_2026!D:D,,0,) -> 20.59 | F9: =C9*E9 -> 20.59 | G9: =_xlfn.XLOOKUP(B9,products_2026!A:A,products_2026!B:B,,0,) -> Crystal Drop Earrings Clipon | H9: =_xlfn.XLOOKUP(B9,products_2026!A:A,products_2026!E:E,,0,) -> SELL0037 | I9: =IFERROR(_xlfn.XLOOKUP(H9,sellers_2026!A:A,sellers_2026!G:G,,0,), "unknown/inactive") -> VIC | J9: =_xlfn.XLOOKUP(H9,sellers_2026!A:A,sellers_2026!B:B,,0,) -> storeshop | L9: Outdoor | M9: 16526.25
A10: ORD000009 | B10: PROD00171 | C10: 1 | D10: =_xlfn.XLOOKUP(order_items!B10,products_2026!A:A,products_2026!C:C,,0,) -> Clothes | E10: =_xlfn.XLOOKUP(B10,products_2026!A:A,products_2026!D:D,,0,) -> 40.28 | F10: =C10*E10 -> 40.28 | G10: =_xlfn.XLOOKUP(B10,products_2026!A:A,products_2026!B:B,,0,) -> Men’s Chino Shorts S | H10: =_xlfn.XLOOKUP(B10,products_2026!A:A,products_2026!E:E,,0,) -> SELL0058 | I10: =IFERROR(_xlfn.XLOOKUP(H10,sellers_2026!A:A,sellers_2026!G:G,,0,), "unknown/inactive") -> QLD | J10: =_xlfn.XLOOKUP(H10,sellers_2026!A:A,sellers_2026!B:B,,0,) -> au6ynzdcy5 | L10: Home | M10: 6457.93
A11: ORD000010 | B11: PROD00240 | C11: 1 | D11: =_xlfn.XLOOKUP(order_items!B11,products_2026!A:A,products_2026!C:C,,0,) -> Outdoor | E11: =_xlfn.XLOOKUP(B11,products_2026!A:A,products_2026!D:D,,0,) -> 51.74 | F11: =C11*E11 -> 51.74 | G11: =_xlfn.XLOOKUP(B11,products_2026!A:A,products_2026!B:B,,0,) -> Garden Ornament Frog | H11: =_xlfn.XLOOKUP(B11,products_2026!A:A,products_2026!E:E,,0,) -> SELL0077 | I11: =IFERROR(_xlfn.XLOOKUP(H11,sellers_2026!A:A,sellers_2026!G:G,,0,), "unknown/inactive") -> ACT | J11: =_xlfn.XLOOKUP(H11,sellers_2026!A:A,sellers_2026!B:B,,0,) -> doorsyout | L11: Electronics | M11: 4385.23
A12: ORD000011 | B12: PROD00019 | C12: 2 | D12: =_xlfn.XLOOKUP(order_items!B12,products_2026!A:A,products_2026!C:C,,0,) -> Beauty | E12: =_xlfn.XLOOKUP(B12,products_2026!A:A,products_2026!D:D,,0,) -> 10.94 | F12: =C12*E12 -> 21.88 | G12: =_xlfn.XLOOKUP(B12,products_2026!A:A,products_2026!B:B,,0,) -> Hydrating Face Mist | H12: =_xlfn.XLOOKUP(B12,products_2026!A:A,products_2026!E:E,,0,) -> SELL0017 | I12: =IFERROR(_xlfn.XLOOKUP(H12,sellers_2026!A:A,sellers_2026!G:G,,0,), "unknown/inactive") -> QLD | J12: =_xlfn.XLOOKUP(H12,sellers_2026!A:A,sellers_2026!B:B,,0,) -> 7e16xoz37j | L12: Clothes | M12: 3487.24
A13: ORD000011 | B13: PROD00240 | C13: 1 | D13: =_xlfn.XLOOKUP(order_items!B13,products_2026!A:A,products_2026!C:C,,0,) -> Outdoor | E13: =_xlfn.XLOOKUP(B13,products_2026!A:A,products_2026!D:D,,0,) -> 51.74 | F13: =C13*E13 -> 51.74 | G13: =_xlfn.XLOOKUP(B13,products_2026!A:A,products_2026!B:B,,0,) -> Garden Ornament Frog | H13: =_xlfn.XLOOKUP(B13,products_2026!A:A,products_2026!E:E,,0,) -> SELL0077 | I13: =IFERROR(_xlfn.XLOOKUP(H13,sellers_2026!A:A,sellers_2026!G:G,,0,), "unknown/inactive") -> ACT | J13: =_xlfn.XLOOKUP(H13,sellers_2026!A:A,sellers_2026!B:B,,0,) -> doorsyout | L13: Health | M13: 2178.86
A14: ORD000011 | B14: PROD00409 | C14: 1 | D14: =_xlfn.XLOOKUP(order_items!B14,products_2026!A:A,products_2026!C:C,,0,) -> Clothes | E14: =_xlfn.XLOOKUP(B14,products_2026!A:A,products_2026!D:D,,0,) -> 64.84 | F14: =C14*E14 -> 64.84 | G14: =_xlfn.XLOOKUP(B14,products_2026!A:A,products_2026!B:B,,0,) -> Portable Camping Chair (Blue) | H14: =_xlfn.XLOOKUP(B14,products_2026!A:A,products_2026!E:E,,0,) -> SELL0092 | I14: =IFERROR(_xlfn.XLOOKUP(H14,sellers_2026!A:A,sellers_2026!G:G,,0,), "unknown/inactive") -> VIC | J14: =_xlfn.XLOOKUP(H14,sellers_2026!A:A,sellers_2026!B:B,,0,) -> dress4beauty | L14: Jewellery | M14: 1829.68
A15: ORD000012 | B15: PROD00059 | C15: 1 | D15: =_xlfn.XLOOKUP(order_items!B15,products_2026!A:A,products_2026!C:C,,0,) -> Beauty | E15: =_xlfn.XLOOKUP(B15,products_2026!A:A,products_2026!D:D,,0,) -> 15.04 | F15: =C15*E15 -> 15.04 | G15: =_xlfn.XLOOKUP(B15,products_2026!A:A,products_2026!B:B,,0,) -> Blending Sponge | H15: =_xlfn.XLOOKUP(B15,products_2026!A:A,products_2026!E:E,,0,) -> SELL0032 | I15: =IFERROR(_xlfn.XLOOKUP(H15,sellers_2026!A:A,sellers_2026!G:G,,0,), "unknown/inactive") -> VIC | J15: =_xlfn.XLOOKUP(H15,sellers_2026!A:A,sellers_2026!B:B,,0,) -> buydongxi25 | L15: Gift_Sets | M15: 1807.1
A16: ORD000012 | B16: PROD00324 | C16: 1 | D16: =_xlfn.XLOOKUP(order_items!B16,products_2026!A:A,products_2026!C:C,,0,) -> Gift_Sets | E16: =_xlfn.XLOOKUP(B16,products_2026!A:A,products_2026!D:D,,0,) -> 33.89 | F16: =C16*E16 -> 33.89 | G16: =_xlfn.XLOOKUP(B16,products_2026!A:A,products_2026!B:B,,0,) -> Mini Plant Starter Kit (Diasy) | H16: =_xlfn.XLOOKUP(B16,products_2026!A:A,products_2026!E:E,,0,) -> SELL0088 | I16: =IFERROR(_xlfn.XLOOKUP(H16,sellers_2026!A:A,sellers_2026!G:G,,0,), "unknown/inactive") -> TAS | J16: =_xlfn.XLOOKUP(H16,sellers_2026!A:A,sellers_2026!B:B,,0,) -> 7ti9lfa6h5 | L16: Toys | M16: 1434.61
A17: ORD000013 | B17: PROD00007 | C17: 1 | D17: =_xlfn.XLOOKUP(order_items!B17,products_2026!A:A,products_2026!C:C,,0,) -> Toys | E17: =_xlfn.XLOOKUP(B17,products_2026!A:A,products_2026!D:D,,0,) -> 38.25 | F17: =C17*E17 -> 38.25 | G17: =_xlfn.XLOOKUP(B17,products_2026!A:A,products_2026!B:B,,0,) -> Slime Lab Blue 8pc | H17: =_xlfn.XLOOKUP(B17,products_2026!A:A,products_2026!E:E,,0,) -> SELL0006 | I17: =IFERROR(_xlfn.XLOOKUP(H17,sellers_2026!A:A,sellers_2026!G:G,,0,), "unknown/inactive") -> VIC | J17: =_xlfn.XLOOKUP(H17,sellers_2026!A:A,sellers_2026!B:B,,0,) -> toysyay | L17: Beauty | M17: 1239.08
A18: ORD000014 | B18: PROD00108 | C18: 2 | D18: =_xlfn.XLOOKUP(order_items!B18,products_2026!A:A,products_2026!C:C,,0,) -> Home | E18: =_xlfn.XLOOKUP(B18,products_2026!A:A,products_2026!D:D,,0,) -> 91.41 | F18: =C18*E18 -> 182.82 | G18: =_xlfn.XLOOKUP(B18,products_2026!A:A,products_2026!B:B,,0,) -> Premium Soy Candle Orange Blossom | H18: =_xlfn.XLOOKUP(B18,products_2026!A:A,products_2026!E:E,,0,) -> SELL0042 | I18: =IFERROR(_xlfn.XLOOKUP(H18,sellers_2026!A:A,sellers_2026!G:G,,0,), "unknown/inactive") -> WA | J18: =_xlfn.XLOOKUP(H18,sellers_2026!A:A,sellers_2026!B:B,,0,) -> beauty490 | L18: Stationery | M18: 351.23
A19: ORD000014 | B19: PROD00120 | C19: 1 | D19: =_xlfn.XLOOKUP(order_items!B19,products_2026!A:A,products_2026!C:C,,0,) -> Clothes | E19: =_xlfn.XLOOKUP(B19,products_2026!A:A,products_2026!D:D,,0,) -> 25.48 | F19: =C19*E19 -> 25.48 | G19: =_xlfn.XLOOKUP(B19,products_2026!A:A,products_2026!B:B,,0,) -> Rain Jacket Red XXS | H19: =_xlfn.XLOOKUP(B19,products_2026!A:A,products_2026!E:E,,0,) -> SELL0045 | I19: =IFERROR(_xlfn.XLOOKUP(H19,sellers_2026!A:A,sellers_2026!G:G,,0,), "unknown/inactive") -> NT | J19: =_xlfn.XLOOKUP(H19,sellers_2026!A:A,sellers_2026!B:B,,0,) -> s22ods7z5m | L19: (blank)
A20: ORD000014 | B20: PROD00159 | C20: 1 | D20: =_xlfn.XLOOKUP(order_items!B20,products_2026!A:A,products_2026!C:C,,0,) -> Toys | E20: =_xlfn.XLOOKUP(B20,products_2026!A:A,products_2026!D:D,,0,) -> 13.7 | F20: =C20*E20 -> 13.7 | G20: =_xlfn.XLOOKUP(B20,products_2026!A:A,products_2026!B:B,,0,) -> Kids Paint Kit (Blue) | H20: =_xlfn.XLOOKUP(B20,products_2026!A:A,products_2026!E:E,,0,) -> SELL0047 | I20: =IFERROR(_xlfn.XLOOKUP(H20,sellers_2026!A:A,sellers_2026!G:G,,0,), "unknown/inactive") -> NT | J20: =_xlfn.XLOOKUP(H20,sellers_2026!A:A,sellers_2026!B:B,,0,) -> toymajoy | L20: Grand Total | M20: 39697.21
A21: ORD000015 | B21: PROD00200 | C21: 1 | D21: =_xlfn.XLOOKUP(order_items!B21,products_2026!A:A,products_2026!C:C,,0,) -> Outdoor | E21: =_xlfn.XLOOKUP(B21,products_2026!A:A,products_2026!D:D,,0,) -> 30.95 | F21: =C21*E21 -> 30.95 | G21: =_xlfn.XLOOKUP(B21,products_2026!A:A,products_2026!B:B,,0,) -> BBQ Cleaning Brush | H21: =_xlfn.XLOOKUP(B21,products_2026!A:A,products_2026!E:E,,0,) -> SELL0067 | I21: =IFERROR(_xlfn.XLOOKUP(H21,sellers_2026!A:A,sellers_2026!G:G,,0,), "unknown/inactive") -> WA | J21: =_xlfn.XLOOKUP(H21,sellers_2026!A:A,sellers_2026!B:B,,0,) -> w71bv3mee1
A22: ORD000016 | B22: PROD00172 | C22: 1 | D22: =_xlfn.XLOOKUP(order_items!B22,products_2026!A:A,products_2026!C:C,,0,) -> Gift_Sets | E22: =_xlfn.XLOOKUP(B22,products_2026!A:A,products_2026!D:D,,0,) -> 29.98 | F22: =C22*E22 -> 29.98 | G22: =_xlfn.XLOOKUP(B22,products_2026!A:A,products_2026!B:B,,0,) -> Coffee Sampler Pack | H22: =_xlfn.XLOOKUP(B22,products_2026!A:A,products_2026!E:E,,0,) -> SELL0058 | I22: =IFERROR(_xlfn.XLOOKUP(H22,sellers_2026!A:A,sellers_2026!G:G,,0,), "unknown/inactive") -> QLD | J22: =_xlfn.XLOOKUP(H22,sellers_2026!A:A,sellers_2026!B:B,,0,) -> au6ynzdcy5
A23: ORD000016 | B23: PROD00228 | C23: 1 | D23: =_xlfn.XLOOKUP(order_items!B23,products_2026!A:A,products_2026!C:C,,0,) -> Home | E23: =_xlfn.XLOOKUP(B23,products_2026!A:A,products_2026!D:D,,0,) -> 64.55 | F23: =C23*E23 -> 64.55 | G23: =_xlfn.XLOOKUP(B23,products_2026!A:A,products_2026!B:B,,0,) -> Carbon Fiber Mug Set | H23: =_xlfn.XLOOKUP(B23,products_2026!A:A,products_2026!E:E,,0,) -> SELL0074 | I23: =IFERROR(_xlfn.XLOOKUP(H23,sellers_2026!A:A,sellers_2026!G:G,,0,), "unknown/inactive") -> NT | J23: =_xlfn.XLOOKUP(H23,sellers_2026!A:A,sellers_2026!B:B,,0,) -> springlesprungle3
A24: ORD000017 | B24: PROD00422 | C24: 1 | D24: =_xlfn.XLOOKUP(order_items!B24,products_2026!A:A,products_2026!C:C,,0,) -> Outdoor | E24: =_xlfn.XLOOKUP(B24,products_2026!A:A,products_2026!D:D,,0,) -> 50.15 | F24: =C24*E24 -> 50.15 | G24: =_xlfn.XLOOKUP(B24,products_2026!A:A,products_2026!B:B,,0,) -> Beach Umbrella - UV50+ Floral | H24: =_xlfn.XLOOKUP(B24,products_2026!A:A,products_2026!E:E,,0,) -> SELL0092 | I24: =IFERROR(_xlfn.XLOOKUP(H24,sellers_2026!A:A,sellers_2026!G:G,,0,), "unknown/inactive") -> VIC | J24: =_xlfn.XLOOKUP(H24,sellers_2026!A:A,sellers_2026!B:B,,0,) -> dress4beauty
A25: ORD000018 | B25: PROD00360 | C25: 1 | D25: =_xlfn.XLOOKUP(order_items!B25,products_2026!A:A,products_2026!C:C,,0,) -> Home | E25: =_xlfn.XLOOKUP(B25,products_2026!A:A,products_2026!D:D,,0,) -> 20.79 | F25: =C25*E25 -> 20.79 | G25: =_xlfn.XLOOKUP(B25,products_2026!A:A,products_2026!B:B,,0,) -> Silicone Laundry Basket - White | H25: =_xlfn.XLOOKUP(B25,products_2026!A:A,products_2026!E:E,,0,) -> SELL0027 | I25: =IFERROR(_xlfn.XLOOKUP(H25,sellers_2026!A:A,sellers_2026!G:G,,0,), "unknown/inactive") -> QLD | J25: =_xlfn.XLOOKUP(H25,sellers_2026!A:A,sellers_2026!B:B,,0,) -> home458
A26: ORD000019 | B26: PROD00084 | C26: 2 | D26: =_xlfn.XLOOKUP(order_items!B26,products_2026!A:A,products_2026!C:C,,0,) -> Home | E26: =_xlfn.XLOOKUP(B26,products_2026!A:A,products_2026!D:D,,0,) -> 46.55 | F26: =C26*E26 -> 93.1 | G26: =_xlfn.XLOOKUP(B26,products_2026!A:A,products_2026!B:B,,0,) -> Stainless Steel Cutting Board | H26: =_xlfn.XLOOKUP(B26,products_2026!A:A,products_2026!E:E,,0,) -> SELL0037 | I26: =IFERROR(_xlfn.XLOOKUP(H26,sellers_2026!A:A,sellers_2026!G:G,,0,), "unknown/inactive") -> VIC | J26: =_xlfn.XLOOKUP(H26,sellers_2026!A:A,sellers_2026!B:B,,0,) -> storeshop | L26: Row Labels | M26: Sum of item_revenue | O26: Row Labels | P26: Sum of product_quantity | R26: Row Labels | S26: Average of product_price | U26: Row Labels | V26: Count of seller_id | X26: Row Labels | Y26: Sum of item_revenue
A27: ORD000020 | B27: PROD00142 | C27: 1 | D27: =_xlfn.XLOOKUP(order_items!B27,products_2026!A:A,products_2026!C:C,,0,) -> Electronics | E27: =_xlfn.XLOOKUP(B27,products_2026!A:A,products_2026!D:D,,0,) -> 62.17 | F27: =C27*E27 -> 62.17 | G27: =_xlfn.XLOOKUP(B27,products_2026!A:A,products_2026!B:B,,0,) -> Bluetooth Speaker - Portable | H27: =_xlfn.XLOOKUP(B27,products_2026!A:A,products_2026!E:E,,0,) -> SELL0051 | I27: =IFERROR(_xlfn.XLOOKUP(H27,sellers_2026!A:A,sellers_2026!G:G,,0,), "unknown/inactive") -> NT | J27: =_xlfn.XLOOKUP(H27,sellers_2026!A:A,sellers_2026!B:B,,0,) -> healthway | L27: Solar Garden Light Set (8 pack) | M27: 923.12 | O27: BBQ Skewers - 12 pack (Bamboo) | P27: 20 | R27: Beauty | S27: 20.6312 | U27: ACT | V27: 43 | X27: ACT | Y27: 2798.11
A28: ORD000021 | B28: PROD00196 | C28: 1 | D28: =_xlfn.XLOOKUP(order_items!B28,products_2026!A:A,products_2026!C:C,,0,) -> Toys | E28: =_xlfn.XLOOKUP(B28,products_2026!A:A,products_2026!D:D,,0,) -> 37.9 | F28: =C28*E28 -> 37.9 | G28: =_xlfn.XLOOKUP(B28,products_2026!A:A,products_2026!B:B,,0,) -> Kite Rainbow | H28: =_xlfn.XLOOKUP(B28,products_2026!A:A,products_2026!E:E,,0,) -> SELL0065 | I28: =IFERROR(_xlfn.XLOOKUP(H28,sellers_2026!A:A,sellers_2026!G:G,,0,), "unknown/inactive") -> ACT | J28: =_xlfn.XLOOKUP(H28,sellers_2026!A:A,sellers_2026!B:B,,0,) -> fq9rb8o3qr | L28: Camping Kettle 5L Navy | M28: 638.9 | O28: Bamboo Picnic Rug Recycled Material | P28: 20 | R28: Clothes | S28: 42.040282 | U28: NSW | V28: 45 | X28: NSW | Y28: 2182.1
A29: ORD000022 | B29: PROD00198 | C29: 1 | D29: =_xlfn.XLOOKUP(order_items!B29,products_2026!A:A,products_2026!C:C,,0,) -> Toys | E29: =_xlfn.XLOOKUP(B29,products_2026!A:A,products_2026!D:D,,0,) -> 24.19 | F29: =C29*E29 -> 24.19 | G29: =_xlfn.XLOOKUP(B29,products_2026!A:A,products_2026!B:B,,0,) -> Light up lawnmower AI powered | H29: =_xlfn.XLOOKUP(B29,products_2026!A:A,products_2026!E:E,,0,) -> SELL0067 | I29: =IFERROR(_xlfn.XLOOKUP(H29,sellers_2026!A:A,sellers_2026!G:G,,0,), "unknown/inactive") -> WA | J29: =_xlfn.XLOOKUP(H29,sellers_2026!A:A,sellers_2026!B:B,,0,) -> w71bv3mee1 | L29: Portable Camping Chair (Yellow) | M29: 601.46 | O29: Snorkel Set - Adult Small | P29: 18 | R29: Electronics | S29: 68.197627 | U29: NT | V29: 135 | X29: NT | Y29: 6315.35
A30: ORD000023 | B30: PROD00362 | C30: 1 | D30: =_xlfn.XLOOKUP(order_items!B30,products_2026!A:A,products_2026!C:C,,0,) -> Home | E30: =_xlfn.XLOOKUP(B30,products_2026!A:A,products_2026!D:D,,0,) -> 115.49 | F30: =C30*E30 -> 115.49 | G30: =_xlfn.XLOOKUP(B30,products_2026!A:A,products_2026!B:B,,0,) -> Memory Foam Pillow Medium Firm | H30: =_xlfn.XLOOKUP(B30,products_2026!A:A,products_2026!E:E,,0,) -> SELL0027 | I30: =IFERROR(_xlfn.XLOOKUP(H30,sellers_2026!A:A,sellers_2026!G:G,,0,), "unknown/inactive") -> QLD | J30: =_xlfn.XLOOKUP(H30,sellers_2026!A:A,sellers_2026!B:B,,0,) -> home458 | L30: Portable Mini Grill | M30: 588.95 | O30: BBQ Cleaning Brush | P30: 15 | R30: Gift_Sets | S30: 29.659423 | U30: QLD | V30: 128 | X30: QLD | Y30: 6542.57
A31: ORD000024 | B31: PROD00197 | C31: 1 | D31: =_xlfn.XLOOKUP(order_items!B31,products_2026!A:A,products_2026!C:C,,0,) -> Health | E31: =_xlfn.XLOOKUP(B31,products_2026!A:A,products_2026!D:D,,0,) -> 40.75 | F31: =C31*E31 -> 40.75 | G31: =_xlfn.XLOOKUP(B31,products_2026!A:A,products_2026!B:B,,0,) -> Blood Pressure Monitor Digital | H31: =_xlfn.XLOOKUP(B31,products_2026!A:A,products_2026!E:E,,0,) -> SELL0066 | I31: =IFERROR(_xlfn.XLOOKUP(H31,sellers_2026!A:A,sellers_2026!G:G,,0,), "unknown/inactive") -> VIC | J31: =_xlfn.XLOOKUP(H31,sellers_2026!A:A,sellers_2026!B:B,,0,) -> healthcarehelp | L31: Snorkel Set - Adult Small | M31: 588.06 | O31: Waterproof Picnic Mat 100x100 | P31: 12 | R31: Health | S31: 47.101707 | U31: SA | V31: 12 | X31: SA | Y31: 680.99
A32: ORD000025 | B32: PROD00211 | C32: 1 | D32: =_xlfn.XLOOKUP(order_items!B32,products_2026!A:A,products_2026!C:C,,0,) -> Home | E32: =_xlfn.XLOOKUP(B32,products_2026!A:A,products_2026!D:D,,0,) -> 14.98 | F32: =C32*E32 -> 14.98 | G32: =_xlfn.XLOOKUP(B32,products_2026!A:A,products_2026!B:B,,0,) -> Essential Oil Diffuser Mains Powered | H32: =_xlfn.XLOOKUP(B32,products_2026!A:A,products_2026!E:E,,0,) -> SELL0070 | I32: =IFERROR(_xlfn.XLOOKUP(H32,sellers_2026!A:A,sellers_2026!G:G,,0,), "unknown/inactive") -> QLD | J32: =_xlfn.XLOOKUP(H32,sellers_2026!A:A,sellers_2026!B:B,,0,) -> homeandaways | L32: BBQ Apron - Blue | M32: 560.49 | O32: Fairy Lights Outdoor Garden String 100 | P32: 12 | R32: Home | S32: 59.057079 | U32: TAS | V32: 158 | X32: TAS | Y32: 8013.18
A33: ORD000025 | B33: PROD00315 | C33: 2 | D33: =_xlfn.XLOOKUP(order_items!B33,products_2026!A:A,products_2026!C:C,,0,) -> Electronics | E33: =_xlfn.XLOOKUP(B33,products_2026!A:A,products_2026!D:D,,0,) -> 36.57 | F33: =C33*E33 -> 73.14 | G33: =_xlfn.XLOOKUP(B33,products_2026!A:A,products_2026!B:B,,0,) -> Portable Power Bank 10,000mAh (Navy) | H33: =_xlfn.XLOOKUP(B33,products_2026!A:A,products_2026!E:E,,0,) -> SELL0088 | I33: =IFERROR(_xlfn.XLOOKUP(H33,sellers_2026!A:A,sellers_2026!G:G,,0,), "unknown/inactive") -> TAS | J33: =_xlfn.XLOOKUP(H33,sellers_2026!A:A,sellers_2026!B:B,,0,) -> 7ti9lfa6h5 | L33: Waterproof Picnic Mat 100x100 | M33: 519.42 | O33: Stainless Steel BBQ Tools Set (Navy) | P33: 10 | R33: Jewellery | S33: 35.403617 | U33: VIC | V33: 186 | X33: VIC | Y33: 9289.27
A34: ORD000025 | B34: PROD00404 | C34: 1 | D34: =_xlfn.XLOOKUP(order_items!B34,products_2026!A:A,products_2026!C:C,,0,) -> Outdoor | E34: =_xlfn.XLOOKUP(B34,products_2026!A:A,products_2026!D:D,,0,) -> 81.02 | F34: =C34*E34 -> 81.02 | G34: =_xlfn.XLOOKUP(B34,products_2026!A:A,products_2026!B:B,,0,) -> BBQ Meat Thermometer Bluetooth | H34: =_xlfn.XLOOKUP(B34,products_2026!A:A,products_2026!E:E,,0,) -> SELL0092 | I34: =IFERROR(_xlfn.XLOOKUP(H34,sellers_2026!A:A,sellers_2026!G:G,,0,), "unknown/inactive") -> VIC | J34: =_xlfn.XLOOKUP(H34,sellers_2026!A:A,sellers_2026!B:B,,0,) -> dress4beauty | L34: Garden Ornament Frog | M34: 517.4 | O34: Vitamin C Serum 50ml | P34: 10 | R34: Outdoor | S34: 47.986186 | U34: WA | V34: 88 | X34: WA | Y34: 3875.64
A35: ORD000026 | B35: PROD00087 | C35: 2 | D35: =_xlfn.XLOOKUP(order_items!B35,products_2026!A:A,products_2026!C:C,,0,) -> Home | E35: =_xlfn.XLOOKUP(B35,products_2026!A:A,products_2026!D:D,,0,) -> 82.88 | F35: =C35*E35 -> 165.76 | G35: =_xlfn.XLOOKUP(B35,products_2026!A:A,products_2026!B:B,,0,) -> Floor Lamp Standing Tall LED | H35: =_xlfn.XLOOKUP(B35,products_2026!A:A,products_2026!E:E,,0,) -> SELL0038 | I35: =IFERROR(_xlfn.XLOOKUP(H35,sellers_2026!A:A,sellers_2026!G:G,,0,), "unknown/inactive") -> SA | J35: =_xlfn.XLOOKUP(H35,sellers_2026!A:A,sellers_2026!B:B,,0,) -> compradadonut | L35: Smart LED Light Bulb | M35: 509.41 | O35: Camping Kettle 5L Navy | P35: 10 | R35: Stationery | S35: 7.5887179 | U35: (blank) | X35: (blank)
A36: ORD000027 | B36: PROD00215 | C36: 2 | D36: =_xlfn.XLOOKUP(order_items!B36,products_2026!A:A,products_2026!C:C,,0,) -> Home | E36: =_xlfn.XLOOKUP(B36,products_2026!A:A,products_2026!D:D,,0,) -> 19.99 | F36: =C36*E36 -> 39.98 | G36: =_xlfn.XLOOKUP(B36,products_2026!A:A,products_2026!B:B,,0,) -> Drawer Organiser 5 sections | H36: =_xlfn.XLOOKUP(B36,products_2026!A:A,products_2026!E:E,,0,) -> SELL0070 | I36: =IFERROR(_xlfn.XLOOKUP(H36,sellers_2026!A:A,sellers_2026!G:G,,0,), "unknown/inactive") -> QLD | J36: =_xlfn.XLOOKUP(H36,sellers_2026!A:A,sellers_2026!B:B,,0,) -> homeandaways | L36: BBQ Meat Thermometer Bluetooth | M36: 486.12 | O36: Garden Ornament Frog | P36: 10 | R36: Toys | S36: 23.85625 | U36: Grand Total | V36: 795 | X36: Grand Total | Y36: 39697.21
A37: ORD000028 | B37: PROD00276 | C37: 1 | D37: =_xlfn.XLOOKUP(order_items!B37,products_2026!A:A,products_2026!C:C,,0,) -> Clothes | E37: =_xlfn.XLOOKUP(B37,products_2026!A:A,products_2026!D:D,,0,) -> 44.13 | F37: =C37*E37 -> 44.13 | G37: =_xlfn.XLOOKUP(B37,products_2026!A:A,products_2026!B:B,,0,) -> Men’s Chino Shorts XL | H37: =_xlfn.XLOOKUP(B37,products_2026!A:A,products_2026!E:E,,0,) -> SELL0086 | I37: =IFERROR(_xlfn.XLOOKUP(H37,sellers_2026!A:A,sellers_2026!G:G,,0,), "unknown/inactive") -> VIC | J37: =_xlfn.XLOOKUP(H37,sellers_2026!A:A,sellers_2026!B:B,,0,) -> clothesforlife | L37: Memory Foam Pillow Medium Firm x 2 | M37: 477.2 | O37: Garden Light Sun Powered No Recharge | P37: 9 | R37: (blank)
A38: ORD000029 | B38: PROD00234 | C38: 1 | D38: =_xlfn.XLOOKUP(order_items!B38,products_2026!A:A,products_2026!C:C,,0,) -> Clothes | E38: =_xlfn.XLOOKUP(B38,products_2026!A:A,products_2026!D:D,,0,) -> 20.75 | F38: =C38*E38 -> 20.75 | G38: =_xlfn.XLOOKUP(B38,products_2026!A:A,products_2026!B:B,,0,) -> Wool Beanie - Navy | H38: =_xlfn.XLOOKUP(B38,products_2026!A:A,products_2026!E:E,,0,) -> SELL0039 | I38: =IFERROR(_xlfn.XLOOKUP(H38,sellers_2026!A:A,sellers_2026!G:G,,0,), "unknown/inactive") -> QLD | J38: =_xlfn.XLOOKUP(H38,sellers_2026!A:A,sellers_2026!B:B,,0,) -> zmkizlf6t6 | L38: BBQ Cleaning Brush | M38: 464.25 | O38: Stainless Steel Grill Basket | P38: 9 | R38: Grand Total | S38: 42.804377
A39: ORD000029 | B39: PROD00425 | C39: 1 | D39: =_xlfn.XLOOKUP(order_items!B39,products_2026!A:A,products_2026!C:C,,0,) -> Outdoor | E39: =_xlfn.XLOOKUP(B39,products_2026!A:A,products_2026!D:D,,0,) -> 26.98 | F39: =C39*E39 -> 26.98 | G39: =_xlfn.XLOOKUP(B39,products_2026!A:A,products_2026!B:B,,0,) -> Stainless Steel BBQ Tools Set (Grey) | H39: =_xlfn.XLOOKUP(B39,products_2026!A:A,products_2026!E:E,,0,) -> SELL0093 | I39: =IFERROR(_xlfn.XLOOKUP(H39,sellers_2026!A:A,sellers_2026!G:G,,0,), "unknown/inactive") -> NT | J39: =_xlfn.XLOOKUP(H39,sellers_2026!A:A,sellers_2026!B:B,,0,) -> millies-outdoor-shop | L39: Fairy Lights Outdoor Garden String 100 | M39: 460.68 | O39: BBQ Skewers - 12 pack (Stainless Steel) | P39: 9
